Traceback (most recent call last):
  File "c:\users\aaron\miniconda37\lib\site-packages\jupyter_cache\executors\utils.py", line 56, in single_nb_execution
    record_timing=False,
  File "c:\users\aaron\miniconda37\lib\site-packages\nbclient\client.py", line 1087, in execute
    return NotebookClient(nb=nb, resources=resources, km=km, **kwargs).execute()
  File "c:\users\aaron\miniconda37\lib\site-packages\nbclient\util.py", line 74, in wrapped
    return just_run(coro(*args, **kwargs))
  File "c:\users\aaron\miniconda37\lib\site-packages\nbclient\util.py", line 53, in just_run
    return loop.run_until_complete(coro)
  File "c:\users\aaron\miniconda37\lib\asyncio\base_events.py", line 587, in run_until_complete
    return future.result()
  File "c:\users\aaron\miniconda37\lib\site-packages\nbclient\client.py", line 541, in async_execute
    cell, index, execution_count=self.code_cells_executed + 1
  File "c:\users\aaron\miniconda37\lib\site-packages\nbclient\client.py", line 832, in async_execute_cell
    self._check_raise_for_error(cell, exec_reply)
  File "c:\users\aaron\miniconda37\lib\site-packages\nbclient\client.py", line 740, in _check_raise_for_error
    raise CellExecutionError.from_cell_and_msg(cell, exec_reply['content'])
nbclient.exceptions.CellExecutionError: An error occurred while executing the following cell:
------------------
# %load sqlite_creatDB_Table.py
# filename:sqlite_CreateDB_Table.py
# function: Python program using Sqlite
# Step1: Create user DB name using Sqlite3.connect("DB name)
# step2: Create Table using CREATE TABLE Table_name
# step3: insert Data value using INSERT INTO invest VALUES

import sqlite3
conndb = sqlite3.connect('chap13_DB.db')
curr = conndb.cursor()

# Create table using CREATE TABLE Table_name
curr.execute(
  "CREATE TABLE invest(date text, trans text, Company text, qty int, price real)")

# Insert a row of data
curr.execute("INSERT INTO invest VALUES ('2016-03-01','BUY','Mediatek',10,120)")

# commit the changes, it means save the data
conndb.commit()

curr.execute('select * from invest')
data_fromDB = curr.fetchall()
print(data_fromDB)

# inserts many records at a time
buy_sell = [('2016-03-28', 'BUY', 'Mediatek', 10, 123.00),
            ('2016-05-02', 'BUY', 'TSMC', 20, 120.00),
            ('2006-05-12', 'SELL', 'Mediatek', 10, 125.00),
            ('2006-05-13', 'SELL', 'TSMC', 20, 125.00),
            ]
curr.executemany('INSERT INTO invest VALUES (?,?,?,?,?)', buy_sell)
conndb.commit()

# fetch the data from DB's table
curr.execute('select * from invest')
data = curr.fetchall()
print(data)

# close the connection .
curr.close()
conndb.close()
------------------

[1;31m---------------------------------------------------------------------------[0m
[1;31mOperationalError[0m                          Traceback (most recent call last)
[1;32m<ipython-input-1-a837fafd5c86>[0m in [0;36m<module>[1;34m[0m
[0;32m     12[0m [1;31m# Create table using CREATE TABLE Table_name[0m[1;33m[0m[1;33m[0m[1;33m[0m[0m
[0;32m     13[0m curr.execute(
[1;32m---> 14[1;33m   "CREATE TABLE invest(date text, trans text, Company text, qty int, price real)")
[0m[0;32m     15[0m [1;33m[0m[0m
[0;32m     16[0m [1;31m# Insert a row of data[0m[1;33m[0m[1;33m[0m[1;33m[0m[0m

[1;31mOperationalError[0m: table invest already exists
OperationalError: table invest already exists

