Traceback (most recent call last):
  File "c:\users\aaron\miniconda37\lib\site-packages\jupyter_cache\executors\utils.py", line 56, in single_nb_execution
    record_timing=False,
  File "c:\users\aaron\miniconda37\lib\site-packages\nbclient\client.py", line 1087, in execute
    return NotebookClient(nb=nb, resources=resources, km=km, **kwargs).execute()
  File "c:\users\aaron\miniconda37\lib\site-packages\nbclient\util.py", line 74, in wrapped
    return just_run(coro(*args, **kwargs))
  File "c:\users\aaron\miniconda37\lib\site-packages\nbclient\util.py", line 53, in just_run
    return loop.run_until_complete(coro)
  File "c:\users\aaron\miniconda37\lib\asyncio\base_events.py", line 587, in run_until_complete
    return future.result()
  File "c:\users\aaron\miniconda37\lib\site-packages\nbclient\client.py", line 541, in async_execute
    cell, index, execution_count=self.code_cells_executed + 1
  File "c:\users\aaron\miniconda37\lib\site-packages\nbclient\client.py", line 832, in async_execute_cell
    self._check_raise_for_error(cell, exec_reply)
  File "c:\users\aaron\miniconda37\lib\site-packages\nbclient\client.py", line 740, in _check_raise_for_error
    raise CellExecutionError.from_cell_and_msg(cell, exec_reply['content'])
nbclient.exceptions.CellExecutionError: An error occurred while executing the following cell:
------------------
import sqlite3
con = sqlite3.connect('school.db')
cur = con.cursor()

# cur.execute('DROP TABLE stu')

sql1 = '''CREATE TABLE IF NOT EXISTS stu ( 
        stuid   INTEGER       PRIMARY KEY, 
        name   VARCHAR(50)   not null, 
        pid     VARCHAR(20)   not null, 
        phone   VARCHAR(20)   not null)'''
cur.execute(sql1)

sql2 = "INSERT INTO stu VALUES (104001,'Claire','B342222','1245667')"
cur.execute(sql2)

record = (104002, 'Marry', 'B342223', '1245668')
sql3 = 'INSERT INTO stu VALUES(?,?,?,?)'
cur.execute(sql3, record)

cur.execute('SELECT * FROM stu')
rows = cur.fetchall()

print(rows)
con.commit()
con.close()
------------------

[1;31m---------------------------------------------------------------------------[0m
[1;31mIntegrityError[0m                            Traceback (most recent call last)
[1;32m<ipython-input-1-e2c4d8cf028e>[0m in [0;36m<module>[1;34m[0m
[0;32m     13[0m [1;33m[0m[0m
[0;32m     14[0m [0msql2[0m [1;33m=[0m [1;34m"INSERT INTO stu VALUES (104001,'Claire','B342222','1245667')"[0m[1;33m[0m[1;33m[0m[0m
[1;32m---> 15[1;33m [0mcur[0m[1;33m.[0m[0mexecute[0m[1;33m([0m[0msql2[0m[1;33m)[0m[1;33m[0m[1;33m[0m[0m
[0m[0;32m     16[0m [1;33m[0m[0m
[0;32m     17[0m [0mrecord[0m [1;33m=[0m [1;33m([0m[1;36m104002[0m[1;33m,[0m [1;34m'Marry'[0m[1;33m,[0m [1;34m'B342223'[0m[1;33m,[0m [1;34m'1245668'[0m[1;33m)[0m[1;33m[0m[1;33m[0m[0m

[1;31mIntegrityError[0m: UNIQUE constraint failed: stu.stuid
IntegrityError: UNIQUE constraint failed: stu.stuid

